/*
 * SPDX-FileCopyrightText: Copyright (c) 2017-2025 Yegor Bugayenko
 * SPDX-License-Identifier: MIT
 */
package org.cactoos.func;

import java.io.IOException;
import java.util.IllegalFormatException;
import java.util.IllegalFormatWidthException;
import org.cactoos.Fallback;
import org.cactoos.iterable.IterableOf;
import org.junit.jupiter.api.Test;
import org.llorllale.cactoos.matchers.Assertion;
import org.llorllale.cactoos.matchers.IsApplicable;
import org.llorllale.cactoos.matchers.Throws;

/**
 * Test case for {@link FuncWithFallback}.
 *
 * @since 0.2
 * @checkstyle JavadocMethodCheck (500 lines)
 */
@SuppressWarnings({"unchecked", "PMD.JUnitTestsShouldIncludeAssert"})
final class FuncWithFallbackTest {

    @Test
    void usesMainFunc() {
        final String expected = "It's success";
        new Assertion<>(
            "Can't use the main function if no exception",
            new FuncWithFallback<>(
                input -> expected,
                new Fallback.From<>(
                    Exception.class,
                    ex -> "In case of failure..."
                )
            ),
            new IsApplicable<>(1, expected)
        ).affirm();
    }

    @Test
    void usesFallback() {
        final String expected = "Never mind";
        new Assertion<>(
            "Can't use the callback in case of exception",
            new FuncWithFallback<>(
                input -> {
                    throw new IOException("Failure");
                },
                new Fallback.From<>(IOException.class, ex -> expected)
            ),
            new IsApplicable<>(1, expected)
        ).affirm();
    }

    @Test
    void usesFallbackOfInterruptedException() {
        final String expected = "Fallback from InterruptedException";
        new Assertion<>(
            "Can't use a fallback from Interrupted in case of exception",
            new FuncWithFallback<>(
                input -> {
                    throw new InterruptedException(
                        "Failure with InterruptedException"
                    );
                },
                new Fallback.From<>(InterruptedException.class, exp -> expected)
            ),
            new IsApplicable<>(1, expected)
        ).affirm();
    }

    @Test
    void usesTheClosestFallback() {
        final String expected = "Fallback from IllegalFormatException";
        new Assertion<>(
            "Can't find the closest fallback",
            new FuncWithFallback<>(
                input -> {
                    throw new IllegalFormatWidthException(1);
                },
                new IterableOf<>(
                    new Fallback.From<>(
                        IllegalArgumentException.class,
                        exp -> "Fallback from IllegalArgumentException"
                    ),
                    new Fallback.From<>(
                        IllegalFormatException.class,
                        exp -> expected
                    )
                )
            ),
            new IsApplicable<>(1, expected)
        ).affirm();
    }

    @Test
    void noFallbackIsProvided() {
        new Assertion<>(
            "Can't find fallback",
            () -> new FuncWithFallback<>(
                input -> {
                    throw new IllegalFormatWidthException(1);
                },
                new IterableOf<>()
            ).apply(1),
            new Throws<>(Exception.class)
        ).affirm();
    }

}
